Workbook

Sheet Suivi Courrier
P2: SYNTHÈSE
P3: Nombre total de courriers | R3: =COUNTA(C17:C1029) -> 713
P4: Courriers ne nécessitant pas de réponse | R4: =COUNTIF(G17:G1029,"Ne nécessite pas de réponse") -> 154
P5: Courriers nécessitant une réponse | R5: =R3-R4 -> 559
P6: Courriers traités (signés) | R6: =COUNT(T17:T1029) -> 510
P7: Courriers répondus dans les délais | R7: =COUNTIF(W17:W1029,"Dans les délais") -> 181
P8: Courriers en alerte JAUNE | R8: =COUNTIF(Q17:Q1029,"JAUNE") -> 4
P9: Courriers en alerte ROUGE | R9: =COUNTIF(Q17:Q1029,"ROUGE") -> 35
P10: Performance (% dans les délais) | R10: =IFERROR(R7/R5,0) -> 0.32379249
P11: Courriers en alerte JAUNE (Directeur) | R11: =COUNTIF(S17:S1029,"JAUNE") -> 0
P12: Courriers en alerte ROUGE (Directeur) | R12: =COUNTIF(S17:S1029,"ROUGE") -> 2
P13: Dossiers soumis en attente de signature Directeur | R13: =COUNTIFS(O17:O1029,"<>",T17:T1029,"") -> 6
B14: DISPOSITIF DE SUIVI INTÉGRAL DU COURRIER (DISC) DE LA DSP — FICHIER DE TEST
A16: N° d'ordre | B16: Date d'arrivée | C16: Référence du courrier Expéditeur | D16: Service d'origine | E16: Référence du courrier MEFP | F16: Référence du courrier DGCPT | G16: Type de courrier (Ordinaire/Confidentiel) | H16: Délai agent applicable (jours) | I16: Objet / Diligences | J16: Division concernée (DRI/DP/DSSE) | K16: Date d'imputation à la division | L16: Date d'imputation à l'agent | M16: Instructions DSP | N16: Agent responsable | O16: Date de soumission du dossier par l'agent | P16: Durée de traitement agent (jours) | Q16: Alerte délai agent (Vert/Jaune/Rouge) | R16: Délai Directeur applicable (jours) | S16: Alerte délai Directeur (Vert/Jaune/Rouge) | T16: Date de signature de la réponse (Directeur) | U16: Durée de traitement Directeur (jours) | V16: Écart global (jours) | W16: Observation
A17: 1 | B17: 46027 | C17: N°0047042 du 05-01-2026 | D17: Structure fictive 09 | F17: REF-B N°000271 du 05-01-2026 | G17: Ordinaire | H17: =IFERROR(VLOOKUP(G17,Paramètres!$B$6:$F$8,2,FALSE()),"") -> 5 | I17: Transmission d'un état récapitulatif fictif | J17: DSSE | K17: 46027 | L17: 46027 | M17: Vérifier la conformité avant signature | N17: Agent DSSE n°3 | O17: 46034 | P17: =IF(G17="Ne nécessite pas de réponse","-",IF(AND(ISNUMBER(B17),ISNUMBER(O17)),O17-B17,"")) -> 7 | Q17: =IF(G17="Ne nécessite pas de réponse","-",IF(O17<>"","-",IF(OR(B17="",H17="",NOT(ISNUMBER(H17)),H17=0),"",IF((TODAY()-B17)/H17<=0.5,"VERT",IF((TODAY()-B17)/H17<=0.8,"JAUNE","ROUGE"))))) -> - | R17: =IFERROR(VLOOKUP(G17,Paramètres!$B$6:$F$8,3,FALSE()),"") -> 2 | S17: =IF(G17="Ne nécessite pas de réponse","-",IF(O17="","",IF(T17<>"","-",IF(OR(R17="",NOT(ISNUMBER(R17)),R17=0),"",IF((TODAY()-O17)/R17<=0.5,"VERT",IF((TODAY()-O17)/R17<=0.8,"JAUNE","ROUGE")))))) -> - | T17: 46035 | U17: =IF(G17="Ne nécessite pas de réponse","-",IF(AND(ISNUMBER(O17),ISNUMBER(T17)),T17-O17,"")) -> 1 | V17: =IF(G17="Ne nécessite pas de réponse","-",IF(AND(ISNUMBER(T17),ISNUMBER(B17),ISNUMBER(H17),ISNUMBER(R17)),T17-(B17+H17+R17),"")) -> 1 | W17: =IF(G17="Ne nécessite pas de réponse","Ne nécessite pas de réponse",IF(T17="","",IF(V17<=0,"Dans les délais","Hors délais"))) -> Hors délais
A18: 2 | B18: 46027 | C18: N°0065246 du 05-01-2026 | D18: Structure fictive 20 | F18: REF-B N°002730 du 05-01-2026 | G18: Ordinaire | H18: =IFERROR(VLOOKUP(G18,Paramètres!$B$6:$F$8,2,FALSE()),"") -> 5 | I18: Convocation à une réunion fictive | J18: DP | K18: 46028 | L18: 46028 | M18: À traiter en priorité | N18: Agent DP n°1 | O18: 46034 | P18: =IF(G18="Ne nécessite pas de réponse","-",IF(AND(ISNUMBER(B18),ISNUMBER(O18)),O18-B18,"")) -> 7 | Q18: =IF(G18="Ne nécessite pas de réponse","-",IF(O18<>"","-",IF(OR(B18="",H18="",NOT(ISNUMBER(H18)),H18=0),"",IF((TODAY()-B18)/H18<=0.5,"VERT",IF((TODAY()-B18)/H18<=0.8,"JAUNE","ROUGE"))))) -> - | R18: =IFERROR(VLOOKUP(G18,Paramètres!$B$6:$F$8,3,FALSE()),"") -> 2 | S18: =IF(G18="Ne nécessite pas de réponse","-",IF(O18="","",IF(T18<>"","-",IF(OR(R18="",NOT(ISNUMBER(R18)),R18=0),"",IF((TODAY()-O18)/R18<=0.5,"VERT",IF((TODAY()-O18)/R18<=0.8,"JAUNE","ROUGE")))))) -> - | T18: 46036 | U18: =IF(G18="Ne nécessite pas de réponse","-",IF(AND(ISNUMBER(O18),ISNUMBER(T18)),T18-O18,"")) -> 2 | V18: =IF(G18="Ne nécessite pas de réponse","-",IF(AND(ISNUMBER(T18),ISNUMBER(B18),ISNUMBER(H18),ISNUMBER(R18)),T18-(B18+H18+R18),"")) -> 2 | W18: =IF(G18="Ne nécessite pas de réponse","Ne nécessite pas de réponse",IF(T18="","",IF(V18<=0,"Dans les délais","Hors délais"))) -> Hors délais
A19: 3 | B19: 46028 | C19: N°0028393 du 06-01-2026 | D19: Structure fictive 09 | F19: REF-B N°008217 du 06-01-2026 | G19: Ne nécessite pas de réponse | H19: =IFERROR(VLOOKUP(G19,Paramètres!$B$6:$F$8,2,FALSE()),"") -> N/A | I19: Transmission d'une note d'orientation fictive | J19: DRI | K19: 46028 | L19: 46028 | M19: Suivi | N19: Agent DRI n°2 | P19: =IF(G19="Ne nécessite pas de réponse","-",IF(AND(ISNUMBER(B19),ISNUMBER(O19)),O19-B19,"")) -> - | Q19: =IF(G19="Ne nécessite pas de réponse","-",IF(O19<>"","-",IF(OR(B19="",H19="",NOT(ISNUMBER(H19)),H19=0),"",IF((TODAY()-B19)/H19<=0.5,"VERT",IF((TODAY()-B19)/H19<=0.8,"JAUNE","ROUGE"))))) -> - | R19: =IFERROR(VLOOKUP(G19,Paramètres!$B$6:$F$8,3,FALSE()),"") -> N/A | S19: =IF(G19="Ne nécessite pas de réponse","-",IF(O19="","",IF(T19<>"","-",IF(OR(R19="",NOT(ISNUMBER(R19)),R19=0),"",IF((TODAY()-O19)/R19<=0.5,"VERT",IF((TODAY()-O19)/R19<=0.8,"JAUNE","ROUGE")))))) -> - | U19: =IF(G19="Ne nécessite pas de réponse","-",IF(AND(ISNUMBER(O19),ISNUMBER(T19)),T19-O19,"")) -> - | V19: =IF(G19="Ne nécessite pas de réponse","-",IF(AND(ISNUMBER(T19),ISNUMBER(B19),ISNUMBER(H19),ISNUMBER(R19)),T19-(B19+H19+R19),"")) -> - | W19: =IF(G19="Ne nécessite pas de réponse","Ne nécessite pas de réponse",IF(T19="","",IF(V19<=0,"Dans les délais","Hors délais"))) -> Ne nécessite pas de réponse
A20: 4 | B20: 46028 | C20: N°0057276 du 06-01-2026 | D20: Structure fictive 11 | F20: REF-B N°008864 du 06-01-2026 | G20: Ordinaire | H20: =IFERROR(VLOOKUP(G20,Paramètres!$B$6:$F$8,2,FALSE()),"") -> 5 | I20: Convocation à une réunion fictive | J20: DP | K20: 46028 | L20: 46028 | M20: Analyse et proposition de réponse | N20: Agent DP n°1 | O20: 46031 | P20: =IF(G20="Ne nécessite pas de réponse","-",IF(AND(ISNUMBER(B20),ISNUMBER(O20)),O20-B20,"")) -> 3 | Q20: =IF(G20="Ne nécessite pas de réponse","-",IF(O20<>"","-",IF(OR(B20="",H20="",NOT(ISNUMBER(H20)),H20=0),"",IF((TODAY()-B20)/H20<=0.5,"VERT",IF((TODAY()-B20)/H20<=0.8,"JAUNE","ROUGE"))))) -> - | R20: =IFERROR(VLOOKUP(G20,Paramètres!$B$6:$F$8,3,FALSE()),"") -> 2 | S20: =IF(G20="Ne nécessite pas de réponse","-",IF(O20="","",IF(T20<>"","-",IF(OR(R20="",NOT(ISNUMBER(R20)),R20=0),"",IF((TODAY()-O20)/R20<=0.5,"VERT",IF((TODAY()-O20)/R20<=0.8,"JAUNE","ROUGE")))))) -> - | T20: 46031 | U20: =IF(G20="Ne nécessite pas de réponse","-",IF(AND(ISNUMBER(O20),ISNUMBER(T20)),T20-O20,"")) -> 0 | V20: =IF(G20="Ne nécessite pas de réponse","-",IF(AND(ISNUMBER(T20),ISNUMBER(B20),ISNUMBER(H20),ISNUMBER(R20)),T20-(B20+H20+R20),"")) -> -4 | W20: =IF(G20="Ne nécessite pas de réponse","Ne nécessite pas de réponse",IF(T20="","",IF(V20<=0,"Dans les délais","Hors délais"))) -> Dans les délais
A21: 5 | B21: 46028 | C21: N°0059016 du 06-01-2026 | D21: Structure fictive 08 | F21: REF-B N°001514 du 06-01-2026 | G21: Ordinaire | H21: =IFERROR(VLOOKUP(G21,Paramètres!$B$6:$F$8,2,FALSE()),"") -> 5 | I21: Demande de documents complémentaires (test) | J21: DRI | K21: 46029 | L21: 46030 | M21: Vérifier la conformité avant signature | N21: Agent DRI n°3 | O21: 46037 | P21: =IF(G21="Ne nécessite pas de réponse","-",IF(AND(ISNUMBER(B21),ISNUMBER(O21)),O21-B21,"")) -> 9 | Q21: =IF(G21="Ne nécessite pas de réponse","-",IF(O21<>"","-",IF(OR(B21="",H21="",NOT(ISNUMBER(H21)),H21=0),"",IF((TODAY()-B21)/H21<=0.5,"VERT",IF((TODAY()-B21)/H21<=0.8,"JAUNE","ROUGE"))))) -> - | R21: =IFERROR(VLOOKUP(G21,Paramètres!$B$6:$F$8,3,FALSE()),"") -> 2 | S21: =IF(G21="Ne nécessite pas de réponse","-",IF(O21="","",IF(T21<>"","-",IF(OR(R21="",NOT(ISNUMBER(R21)),R21=0),"",IF((TODAY()-O21)/R21<=0.5,"VERT",IF((TODAY()-O21)/R21<=0.8,"JAUNE","ROUGE")))))) -> - | T21: 46037 | U21: =IF(G21="Ne nécessite pas de réponse","-",IF(AND(ISNUMBER(O21),ISNUMBER(T21)),T21-O21,"")) -> 0 | V21: =IF(G21="Ne nécessite pas de réponse","-",IF(AND(ISNUMBER(T21),ISNUMBER(B21),ISNUMBER(H21),ISNUMBER(R21)),T21-(B21+H21+R21),"")) -> 2 | W21: =IF(G21="Ne nécessite pas de réponse","Ne nécessite pas de réponse",IF(T21="","",IF(V21<=0,"Dans les délais","Hors délais"))) -> Hors délais
A22: 6 | B22: 46028 | C22: N°0014011 du 06-01-2026 | D22: Structure fictive 06 | E22: REF-A N°005409 du 06-01-2026 | F22: REF-B N°006480 du 06-01-2026 | G22: Ordinaire | H22: =IFERROR(VLOOKUP(G22,Paramètres!$B$6:$F$8,2,FALSE()),"") -> 5 | I22: Transmission d'un rapport annuel fictif | J22: DSSE | K22: 46028 | L22: 46029 | M22: Suivi | N22: Agent DSSE n°3 | O22: 46035 | P22: =IF(G22="Ne nécessite pas de réponse","-",IF(AND(ISNUMBER(B22),ISNUMBER(O22)),O22-B22,"")) -> 7 | Q22: =IF(G22="Ne nécessite pas de réponse","-",IF(O22<>"","-",IF(OR(B22="",H22="",NOT(ISNUMBER(H22)),H22=0),"",IF((TODAY()-B22)/H22<=0.5,"VERT",IF((TODAY()-B22)/H22<=0.8,"JAUNE","ROUGE"))))) -> - | R22: =IFERROR(VLOOKUP(G22,Paramètres!$B$6:$F$8,3,FALSE()),"") -> 2 | S22: =IF(G22="Ne nécessite pas de réponse","-",IF(O22="","",IF(T22<>"","-",IF(OR(R22="",NOT(ISNUMBER(R22)),R22=0),"",IF((TODAY()-O22)/R22<=0.5,"VERT",IF((TODAY()-O22)/R22<=0.8,"JAUNE","ROUGE")))))) -> - | T22: 46038 | U22: =IF(G22="Ne nécessite pas de réponse","-",IF(AND(ISNUMBER(O22),ISNUMBER(T22)),T22-O22,"")) -> 3 | V22: =IF(G22="Ne nécessite pas de réponse","-",IF(AND(ISNUMBER(T22),ISNUMBER(B22),ISNUMBER(H22),ISNUMBER(R22)),T22-(B22+H22+R22),"")) -> 3 | W22: =IF(G22="Ne nécessite pas de réponse","Ne nécessite pas de réponse",IF(T22="","",IF(V22<=0,"Dans les délais","Hors délais"))) -> Hors délais
A23: 7 | B23: 46029 | C23: N°0066324 du 07-01-2026 | D23: Structure fictive 09 | F23: REF-B N°004973 du 07-01-2026 | G23: Ordinaire | H23: =IFERROR(VLOOKUP(G23,Paramètres!$B$6:$F$8,2,FALSE()),"") -> 5 | I23: Transmission d'un rapport trimestriel fictif | J23: DSSE | K23: 46029 | L23: 46030 | M23: Préparer une note de réponse synthétique | N23: Agent DSSE n°1 | O23: 46035 | P23: =IF(G23="Ne nécessite pas de réponse","-",IF(AND(ISNUMBER(B23),ISNUMBER(O23)),O23-B23,"")) -> 6 | Q23: =IF(G23="Ne nécessite pas de réponse","-",IF(O23<>"","-",IF(OR(B23="",H23="",NOT(ISNUMBER(H23)),H23=0),"",IF((TODAY()-B23)/H23<=0.5,"VERT",IF((TODAY()-B23)/H23<=0.8,"JAUNE","ROUGE"))))) -> - | R23: =IFERROR(VLOOKUP(G23,Paramètres!$B$6:$F$8,3,FALSE()),"") -> 2 | S23: =IF(G23="Ne nécessite pas de réponse","-",IF(O23="","",IF(T23<>"","-",IF(OR(R23="",NOT(ISNUMBER(R23)),R23=0),"",IF((TODAY()-O23)/R23<=0.5,"VERT",IF((TODAY()-O23)/R23<=0.8,"JAUNE","ROUGE")))))) -> - | T23: 46037 | U23: =IF(G23="Ne nécessite pas de réponse","-",IF(AND(ISNUMBER(O23),ISNUMBER(T23)),T23-O23,"")) -> 2 | V23: =IF(G23="Ne nécessite pas de réponse","-",IF(AND(ISNUMBER(T23),ISNUMBER(B23),ISNUMBER(H23),ISNUMBER(R23)),T23-(B23+H23+R23),"")) -> 1 | W23: =IF(G23="Ne nécessite pas de réponse","Ne nécessite pas de réponse",IF(T23="","",IF(V23<=0,"Dans les délais","Hors délais"))) -> Hors délais
A24: 8 | B24: 46029 | C24: N°0042356 du 07-01-2026 | D24: Structure fictive 09 | E24: REF-A N°006392 du 07-01-2026 | F24: REF-B N°005712 du 07-01-2026 | G24: Ordinaire | H24: =IFERROR(VLOOKUP(G24,Paramètres!$B$6:$F$8,2,FALSE()),"") -> 5 | I24: Transmission d'un état récapitulatif fictif | J24: DSSE | K24: 46030 | L24: 46031 | M24: Analyse et proposition de réponse | N24: Agent DSSE n°1 | O24: 46037 | P24: =IF(G24="Ne nécessite pas de réponse","-",IF(AND(ISNUMBER(B24),ISNUMBER(O24)),O24-B24,"")) -> 8 | Q24: =IF(G24="Ne nécessite pas de réponse","-",IF(O24<>"","-",IF(OR(B24="",H24="",NOT(ISNUMBER(H24)),H24=0),"",IF((TODAY()-B24)/H24<=0.5,"VERT",IF((TODAY()-B24)/H24<=0.8,"JAUNE","ROUGE"))))) -> - | R24: =IFERROR(VLOOKUP(G24,Paramètres!$B$6:$F$8,3,FALSE()),"") -> 2 | S24: =IF(G24="Ne nécessite pas de réponse","-",IF(O24="","",IF(T24<>"","-",IF(OR(R24="",NOT(ISNUMBER(R24)),R24=0),"",IF((TODAY()-O24)/R24<=0.5,"VERT",IF((TODAY()-O24)/R24<=0.8,"JAUNE","ROUGE")))))) -> - | T24: 46038 | U24: =IF(G24="Ne nécessite pas de réponse","-",IF(AND(ISNUMBER(O24),ISNUMBER(T24)),T24-O24,"")) -> 1 | V24: =IF(G24="Ne nécessite pas de réponse","-",IF(AND(ISNUMBER(T24),ISNUMBER(B24),ISNUMBER(H24),ISNUMBER(R24)),T24-(B24+H24+R24),"")) -> 2 | W24: =IF(G24="Ne nécessite pas de réponse","Ne nécessite pas de réponse",IF(T24="","",IF(V24<=0,"Dans les délais","Hors délais"))) -> Hors délais
A25: 9 | B25: 46029 | C25: N°0037686 du 07-01-2026 | D25: Structure fictive 03 | E25: REF-A N°003914 du 07-01-2026 | F25: REF-B N°007357 du 07-01-2026 | G25: Confidentiel | H25: =IFERROR(VLOOKUP(G25,Paramètres!$B$6:$F$8,2,FALSE()),"") -> 5 | I25: Demande de précisions sur un tableau de bord fictif | J25: DSSE | K25: 46029 | L25: 46030 | M25: Examen et avis motivé | N25: Agent DSSE n°2 | O25: 46035 | P25: =IF(G25="Ne nécessite pas de réponse","-",IF(AND(ISNUMBER(B25),ISNUMBER(O25)),O25-B25,"")) -> 6 | Q25: =IF(G25="Ne nécessite pas de réponse","-",IF(O25<>"","-",IF(OR(B25="",H25="",NOT(ISNUMBER(H25)),H25=0),"",IF((TODAY()-B25)/H25<=0.5,"VERT",IF((TODAY()-B25)/H25<=0.8,"JAUNE","ROUGE"))))) -> - | R25: =IFERROR(VLOOKUP(G25,Paramètres!$B$6:$F$8,3,FALSE()),"") -> 2 | S25: =IF(G25="Ne nécessite pas de réponse","-",IF(O25="","",IF(T25<>"","-",IF(OR(R25="",NOT(ISNUMBER(R25)),R25=0),"",IF((TODAY()-O25)/R25<=0.5,"VERT",IF((TODAY()-O25)/R25<=0.8,"JAUNE","ROUGE")))))) -> - | T25: 46036 | U25: =IF(G25="Ne nécessite pas de réponse","-",IF(AND(ISNUMBER(O25),ISNUMBER(T25)),T25-O25,"")) -> 1 | V25: =IF(G25="Ne nécessite pas de réponse","-",IF(AND(ISNUMBER(T25),ISNUMBER(B25),ISNUMBER(H25),ISNUMBER(R25)),T25-(B25+H25+R25),"")) -> 0 | W25: =IF(G25="Ne nécessite pas de réponse","Ne nécessite pas de réponse",IF(T25="","",IF(V25<=0,"Dans les délais","Hors délais"))) -> Dans les délais
A26: 10 | B26: 46029 | C26: N°0081785 du 07-01-2026 | D26: Structure fictive 04 | F26: REF-B N°006411 du 07-01-2026 | G26: Ne nécessite pas de réponse | H26: =IFERROR(VLOOKUP(G26,Paramètres!$B$6:$F$8,2,FALSE()),"") -> N/A | I26: Examen d'un document de planification fictif | J26: DSSE | K26: 46029 | L26: 46030 | M26: Examen et avis motivé | N26: Agent DSSE n°2 | P26: =IF(G26="Ne nécessite pas de réponse","-",IF(AND(ISNUMBER(B26),ISNUMBER(O26)),O26-B26,"")) -> - | Q26: =IF(G26="Ne nécessite pas de réponse","-",IF(O26<>"","-",IF(OR(B26="",H26="",NOT(ISNUMBER(H26)),H26=0),"",IF((TODAY()-B26)/H26<=0.5,"VERT",IF((TODAY()-B26)/H26<=0.8,"JAUNE","ROUGE"))))) -> - | R26: =IFERROR(VLOOKUP(G26,Paramètres!$B$6:$F$8,3,FALSE()),"") -> N/A | S26: =IF(G26="Ne nécessite pas de réponse","-",IF(O26="","",IF(T26<>"","-",IF(OR(R26="",NOT(ISNUMBER(R26)),R26=0),"",IF((TODAY()-O26)/R26<=0.5,"VERT",IF((TODAY()-O26)/R26<=0.8,"JAUNE","ROUGE")))))) -> - | U26: =IF(G26="Ne nécessite pas de réponse","-",IF(AND(ISNUMBER(O26),ISNUMBER(T26)),T26-O26,"")) -> - | V26: =IF(G26="Ne nécessite pas de réponse","-",IF(AND(ISNUMBER(T26),ISNUMBER(B26),ISNUMBER(H26),ISNUMBER(R26)),T26-(B26+H26+R26),"")) -> - | W26: =IF(G26="Ne nécessite pas de réponse","Ne nécessite pas de réponse",IF(T26="","",IF(V26<=0,"Dans les délais","Hors délais"))) -> Ne nécessite pas de réponse
A27: 11 | B27: 46029 | C27: N°0034393 du 07-01-2026 | D27: Structure fictive 11 | F27: REF-B N°001016 du 07-01-2026 | G27: Ne nécessite pas de réponse | H27: =IFERROR(VLOOKUP(G27,Paramètres!$B$6:$F$8,2,FALSE()),"") -> N/A | I27: Projet de texte soumis pour observations (données fictives) | J27: DRI | K27: 46029 | L27: 46029 | M27: Préparer une note de réponse synthétique | N27: Agent DRI n°2 | P27: =IF(G27="Ne nécessite pas de réponse","-",IF(AND(ISNUMBER(B27),ISNUMBER(O27)),O27-B27,"")) -> - | Q27: =IF(G27="Ne nécessite pas de réponse","-",IF(O27<>"","-",IF(OR(B27="",H27="",NOT(ISNUMBER(H27)),H27=0),"",IF((TODAY()-B27)/H27<=0.5,"VERT",IF((TODAY()-B27)/H27<=0.8,"JAUNE","ROUGE"))))) -> - | R27: =IFERROR(VLOOKUP(G27,Paramètres!$B$6:$F$8,3,FALSE()),"") -> N/A | S27: =IF(G27="Ne nécessite pas de réponse","-",IF(O27="","",IF(T27<>"","-",IF(OR(R27="",NOT(ISNUMBER(R27)),R27=0),"",IF((TODAY()-O27)/R27<=0.5,"VERT",IF((TODAY()-O27)/R27<=0.8,"JAUNE","ROUGE")))))) -> - | U27: =IF(G27="Ne nécessite pas de réponse","-",IF(AND(ISNUMBER(O27),ISNUMBER(T27)),T27-O27,"")) -> - | V27: =IF(G27="Ne nécessite pas de réponse","-",IF(AND(ISNUMBER(T27),ISNUMBER(B27),ISNUMBER(H27),ISNUMBER(R27)),T27-(B27+H27+R27),"")) -> - | W27: =IF(G27="Ne nécessite pas de réponse","Ne nécessite pas de réponse",IF(T27="","",IF(V27<=0,"Dans les délais","Hors délais"))) -> Ne nécessite pas de réponse
A28: 12 | B28: 46029 | C28: N°0023984 du 07-01-2026 | D28: Structure fictive 15 | F28: REF-B N°008144 du 07-01-2026 | G28: Ordinaire | H28: =IFERROR(VLOOKUP(G28,Paramètres!$B$6:$F$8,2,FALSE()),"") -> 5 | I28: Transmission de pièces justificatives fictives | J28: DSSE | K28: 46030 | L28: 46030 | M28: À traiter en priorité | N28: Agent DSSE n°3 | O28: 46035 | P28: =IF(G28="Ne nécessite pas de réponse","-",IF(AND(ISNUMBER(B28),ISNUMBER(O28)),O28-B28,"")) -> 6 | Q28: =IF(G28="Ne nécessite pas de réponse","-",IF(O28<>"","-",IF(OR(B28="",H28="",NOT(ISNUMBER(H28)),H28=0),"",IF((TODAY()-B28)/H28<=0.5,"VERT",IF((TODAY()-B28)/H28<=0.8,"JAUNE","ROUGE"))))) -> - | R28: =IFERROR(VLOOKUP(G28,Paramètres!$B$6:$F$8,3,FALSE()),"") -> 2 | S28: =IF(G28="Ne nécessite pas de réponse","-",IF(O28="","",IF(T28<>"","-",IF(OR(R28="",NOT(ISNUMBER(R28)),R28=0),"",IF((TODAY()-O28)/R28<=0.5,"VERT",IF((TODAY()-O28)/R28<=0.8,"JAUNE","ROUGE")))))) -> - | T28: 46036 | U28: =IF(G28="Ne nécessite pas de réponse","-",IF(AND(ISNUMBER(O28),ISNUMBER(T28)),T28-O28,"")) -> 1 | V28: =IF(G28="Ne nécessite pas de réponse","-",IF(AND(ISNUMBER(T28),ISNUMBER(B28),ISNUMBER(H28),ISNUMBER(R28)),T28-(B28+H28+R28),"")) -> 0 | W28: =IF(G28="Ne nécessite pas de réponse","Ne nécessite pas de réponse",IF(T28="","",IF(V28<=0,"Dans les délais","Hors délais"))) -> Dans les délais
A29: 13 | B29: 46030 | C29: N°0001777 du 08-01-2026 | D29: Structure fictive 07 | F29: REF-B N°000823 du 08-01-2026 | G29: Ordinaire | H29: =IFERROR(VLOOKUP(G29,Paramètres!$B$6:$F$8,2,FALSE()),"") -> 5 | I29: Projet de texte soumis pour observations (données fictives) | J29: DRI | K29: 46031 | L29: 46034 | M29: Préparer une note de réponse synthétique | N29: Agent DRI n°1 | O29: 46036 | P29: =IF(G29="Ne nécessite pas de réponse","-",IF(AND(ISNUMBER(B29),ISNUMBER(O29)),O29-B29,"")) -> 6 | Q29: =IF(G29="Ne nécessite pas de réponse","-",IF(O29<>"","-",IF(OR(B29="",H29="",NOT(ISNUMBER(H29)),H29=0),"",IF((TODAY()-B29)/H29<=0.5,"VERT",IF((TODAY()-B29)/H29<=0.8,"JAUNE","ROUGE"))))) -> - | R29: =IFERROR(VLOOKUP(G29,Paramètres!$B$6:$F$8,3,FALSE()),"") -> 2 | S29: =IF(G29="Ne nécessite pas de réponse","-",IF(O29="","",IF(T29<>"","-",IF(OR(R29="",NOT(ISNUMBER(R29)),R29=0),"",IF((TODAY()-O29)/R29<=0.5,"VERT",IF((TODAY()-O29)/R29<=0.8,"JAUNE","ROUGE")))))) -> - | T29: 46038 | U29: =IF(G29="Ne nécessite pas de réponse","-",IF(AND(ISNUMBER(O29),ISNUMBER(T29)),T29-O29,"")) -> 2 | V29: =IF(G29="Ne nécessite pas de réponse","-",IF(AND(ISNUMBER(T29),ISNUMBER(B29),ISNUMBER(H29),ISNUMBER(R29)),T29-(B29+H29+R29),"")) -> 1 | W29: =IF(G29="Ne nécessite pas de réponse","Ne nécessite pas de réponse",IF(T29="","",IF(V29<=0,"Dans les délais","Hors délais"))) -> Hors délais
A30: 14 | B30: 46030 | C30: N°0065546 du 08-01-2026 | D30: Structure fictive 05 | F30: REF-B N°008281 du 08-01-2026 | G30: Ordinaire | H30: =IFERROR(VLOOKUP(G30,Paramètres!$B$6:$F$8,2,FALSE()),"") -> 5 | I30: Transmission d'un état récapitulatif fictif | J30: DSSE | K30: 46031 | L30: 46031 | M30: Analyse et proposition de réponse | N30: Agent DSSE n°2 | O30: 46034 | P30: =IF(G30="Ne nécessite pas de réponse","-",IF(AND(ISNUMBER(B30),ISNUMBER(O30)),O30-B30,"")) -> 4 | Q30: =IF(G30="Ne nécessite pas de réponse","-",IF(O30<>"","-",IF(OR(B30="",H30="",NOT(ISNUMBER(H30)),H30=0),"",IF((TODAY()-B30)/H30<=0.5,"VERT",IF((TODAY()-B30)/H30<=0.8,"JAUNE","ROUGE"))))) -> - | R30: =IFERROR(VLOOKUP(G30,Paramètres!$B$6:$F$8,3,FALSE()),"") -> 2 | S30: =IF(G30="Ne nécessite pas de réponse","-",IF(O30="","",IF(T30<>"","-",IF(OR(R30="",NOT(ISNUMBER(R30)),R30=0),"",IF((TODAY()-O30)/R30<=0.5,"VERT",IF((TODAY()-O30)/R30<=0.8,"JAUNE","ROUGE")))))) -> - | T30: 46035 | U30: =IF(G30="Ne nécessite pas de réponse","-",IF(AND(ISNUMBER(O30),ISNUMBER(T30)),T30-O30,"")) -> 1 | V30: =IF(G30="Ne nécessite pas de réponse","-",IF(AND(ISNUMBER(T30),ISNUMBER(B30),ISNUMBER(H30),ISNUMBER(R30)),T30-(B30+H30+R30),"")) -> -2 | W30: =IF(G30="Ne nécessite pas de réponse","Ne nécessite pas de réponse",IF(T30="","",IF(V30<=0,"Dans les délais","Hors délais"))) -> Dans les délais
A31: 15 | B31: 46030 | C31: N°0084847 du 08-01-2026 | D31: Structure fictive 09 | F31: REF-B N°002920 du 08-01-2026 | G31: Ordinaire | H31: =IFERROR(VLOOKUP(G31,Paramètres!$B$6:$F$8,2,FALSE()),"") -> 5 | I31: Demande d'information sur un dossier de test | J31: DRI | K31: 46030 | L31: 46030 | M31: À traiter en priorité | N31: Agent DRI n°1 | O31: 46041 | P31: =IF(G31="Ne nécessite pas de réponse","-",IF(AND(ISNUMBER(B31),ISNUMBER(O31)),O31-B31,"")) -> 11 | Q31: =IF(G31="Ne nécessite pas de réponse","-",IF(O31<>"","-",IF(OR(B31="",H31="",NOT(ISNUMBER(H31)),H31=0),"",IF((TODAY()-B31)/H31<=0.5,"VERT",IF((TODAY()-B31)/H31<=0.8,"JAUNE","ROUGE"))))) -> - | R31: =IFERROR(VLOOKUP(G31,Paramètres!$B$6:$F$8,3,FALSE()),"") -> 2 | S31: =IF(G31="Ne nécessite pas de réponse","-",IF(O31="","",IF(T31<>"","-",IF(OR(R31="",NOT(ISNUMBER(R31)),R31=0),"",IF((TODAY()-O31)/R31<=0.5,"VERT",IF((TODAY()-O31)/R31<=0.8,"JAUNE","ROUGE")))))) -> - | T31: 46043 | U31: =IF(G31="Ne nécessite pas de réponse","-",IF(AND(ISNUMBER(O31),ISNUMBER(T31)),T31-O31,"")) -> 2 | V31: =IF(G31="Ne nécessite pas de réponse","-",IF(AND(ISNUMBER(T31),ISNUMBER(B31),ISNUMBER(H31),ISNUMBER(R31)),T31-(B31+H31+R31),"")) -> 6 | W31: =IF(G31="Ne nécessite pas de réponse","Ne nécessite pas de réponse",IF(T31="","",IF(V31<=0,"Dans les délais","Hors délais"))) -> Hors délais
A32: 16 | B32: 46030 | C32: N°0008941 du 08-01-2026 | D32: Structure fictive 09 | E32: REF-A N°018340 du 08-01-2026 | F32: REF-B N°009165 du 08-01-2026 | G32: Ne nécessite pas de réponse | H32: =IFERROR(VLOOKUP(G32,Paramètres!$B$6:$F$8,2,FALSE()),"") -> N/A | I32: Demande d'information sur un dossier de test | J32: DRI | K32: 46030 | L32: 46030 | M32: Suivi | N32: Agent DRI n°1 | P32: =IF(G32="Ne nécessite pas de réponse","-",IF(AND(ISNUMBER(B32),ISNUMBER(O32)),O32-B32,"")) -> - | Q32: =IF(G32="Ne nécessite pas de réponse","-",IF(O32<>"","-",IF(OR(B32="",H32="",NOT(ISNUMBER(H32)),H32=0),"",IF((TODAY()-B32)/H32<=0.5,"VERT",IF((TODAY()-B32)/H32<=0.8,"JAUNE","ROUGE"))))) -> - | R32: =IFERROR(VLOOKUP(G32,Paramètres!$B$6:$F$8,3,FALSE()),"") -> N/A | S32: =IF(G32="Ne nécessite pas de réponse","-",IF(O32="","",IF(T32<>"","-",IF(OR(R32="",NOT(ISNUMBER(R32)),R32=0),"",IF((TODAY()-O32)/R32<=0.5,"VERT",IF((TODAY()-O32)/R32<=0.8,"JAUNE","ROUGE")))))) -> - | U32: =IF(G32="Ne nécessite pas de réponse","-",IF(AND(ISNUMBER(O32),ISNUMBER(T32)),T32-O32,"")) -> - | V32: =IF(G32="Ne nécessite pas de réponse","-",IF(AND(ISNUMBER(T32),ISNUMBER(B32),ISNUMBER(H32),ISNUMBER(R32)),T32-(B32+H32+R32),"")) -> - | W32: =IF(G32="Ne nécessite pas de réponse","Ne nécessite pas de réponse",IF(T32="","",IF(V32<=0,"Dans les délais","Hors délais"))) -> Ne nécessite pas de réponse
A33: 17 | B33: 46034 | C33: N°0052307 du 12-01-2026 | D33: Structure fictive 03 | F33: REF-B N°000360 du 12-01-2026 | G33: Ne nécessite pas de réponse | H33: =IFERROR(VLOOKUP(G33,Paramètres!$B$6:$F$8,2,FALSE()),"") -> N/A | I33: Demande d'information sur un dossier de test | J33: DRI | K33: 46034 | L33: 46034 | M33: Préparer une note de réponse synthétique | N33: Agent DRI n°2 | P33: =IF(G33="Ne nécessite pas de réponse","-",IF(AND(ISNUMBER(B33),ISNUMBER(O33)),O33-B33,"")) -> - | Q33: =IF(G33="Ne nécessite pas de réponse","-",IF(O33<>"","-",IF(OR(B33="",H33="",NOT(ISNUMBER(H33)),H33=0),"",IF((TODAY()-B33)/H33<=0.5,"VERT",IF((TODAY()-B33)/H33<=0.8,"JAUNE","ROUGE"))))) -> - | R33: =IFERROR(VLOOKUP(G33,Paramètres!$B$6:$F$8,3,FALSE()),"") -> N/A | S33: =IF(G33="Ne nécessite pas de réponse","-",IF(O33="","",IF(T33<>"","-",IF(OR(R33="",NOT(ISNUMBER(R33)),R33=0),"",IF((TODAY()-O33)/R33<=0.5,"VERT",IF((TODAY()-O33)/R33<=0.8,"JAUNE","ROUGE")))))) -> - | U33: =IF(G33="Ne nécessite pas de réponse","-",IF(AND(ISNUMBER(O33),ISNUMBER(T33)),T33-O33,"")) -> - | V33: =IF(G33="Ne nécessite pas de réponse","-",IF(AND(ISNUMBER(T33),ISNUMBER(B33),ISNUMBER(H33),ISNUMBER(R33)),T33-(B33+H33+R33),"")) -> - | W33: =IF(G33="Ne nécessite pas de réponse","Ne nécessite pas de réponse",IF(T33="","",IF(V33<=0,"Dans les délais","Hors délais"))) -> Ne nécessite pas de réponse
A34: 18 | B34: 46034 | C34: N°0019421 du 12-01-2026 | D34: Structure fictive 19 | F34: REF-B N°005440 du 12-01-2026 | G34: Ordinaire | H34: =IFERROR(VLOOKUP(G34,Paramètres!$B$6:$F$8,2,FALSE()),"") -> 5 | I34: Transmission d'un rapport trimestriel fictif | J34: DSSE | K34: 46035 | L34: 46035 | M34: Analyse et proposition de réponse | N34: Agent DSSE n°2 | O34: 46041 | P34: =IF(G34="Ne nécessite pas de réponse","-",IF(AND(ISNUMBER(B34),ISNUMBER(O34)),O34-B34,"")) -> 7 | Q34: =IF(G34="Ne nécessite pas de réponse","-",IF(O34<>"","-",IF(OR(B34="",H34="",NOT(ISNUMBER(H34)),H34=0),"",IF((TODAY()-B34)/H34<=0.5,"VERT",IF((TODAY()-B34)/H34<=0.8,"JAUNE","ROUGE"))))) -> - | R34: =IFERROR(VLOOKUP(G34,Paramètres!$B$6:$F$8,3,FALSE()),"") -> 2 | S34: =IF(G34="Ne nécessite pas de réponse","-",IF(O34="","",IF(T34<>"","-",IF(OR(R34="",NOT(ISNUMBER(R34)),R34=0),"",IF((TODAY()-O34)/R34<=0.5,"VERT",IF((TODAY()-O34)/R34<=0.8,"JAUNE","ROUGE")))))) -> - | T34: 46042 | U34: =IF(G34="Ne nécessite pas de réponse","-",IF(AND(ISNUMBER(O34),ISNUMBER(T34)),T34-O34,"")) -> 1 | V34: =IF(G34="Ne nécessite pas de réponse","-",IF(AND(ISNUMBER(T34),ISNUMBER(B34),ISNUMBER(H34),ISNUMBER(R34)),T34-(B34+H34+R34),"")) -> 1 | W34: =IF(G34="Ne nécessite pas de réponse","Ne nécessite pas de réponse",IF(T34="","",IF(V34<=0,"Dans les délais","Hors délais"))) -> Hors délais
A35: 19 | B35: 46034 | C35: N°0098051 du 12-01-2026 | D35: Structure fictive 14 | F35: REF-B N°001566 du 12-01-2026 | G35: Confidentiel | H35: =IFERROR(VLOOKUP(G35,Paramètres!$B$6:$F$8,2,FALSE()),"") -> 5 | I35: Demande de désignation d'un point focal (test) | J35: DP | K35: 46035 | L35: 46035 | M35: À traiter en priorité | N35: Agent DP n°2 | O35: 46038 | P35: =IF(G35="Ne nécessite pas de réponse","-",IF(AND(ISNUMBER(B35),ISNUMBER(O35)),O35-B35,"")) -> 4 | Q35: =IF(G35="Ne nécessite pas de réponse","-",IF(O35<>"","-",IF(OR(B35="",H35="",NOT(ISNUMBER(H35)),H35=0),"",IF((TODAY()-B35)/H35<=0.5,"VERT",IF((TODAY()-B35)/H35<=0.8,"JAUNE","ROUGE"))))) -> - | R35: =IFERROR(VLOOKUP(G35,Paramètres!$B$6:$F$8,3,FALSE()),"") -> 2 | S35: =IF(G35="Ne nécessite pas de réponse","-",IF(O35="","",IF(T35<>"","-",IF(OR(R35="",NOT(ISNUMBER(R35)),R35=0),"",IF((TODAY()-O35)/R35<=0.5,"VERT",IF((TODAY()-O35)/R35<=0.8,"JAUNE","ROUGE")))))) -> - | T35: 46042 | U35: =IF(G35="Ne nécessite pas de réponse","-",IF(AND(ISNUMBER(O35),ISNUMBER(T35)),T35-O35,"")) -> 4 | V35: =IF(G35="Ne nécessite pas de réponse","-",IF(AND(ISNUMBER(T35),ISNUMBER(B35),ISNUMBER(H35),ISNUMBER(R35)),T35-(B35+H35+R35),"")) -> 1 | W35: =IF(G35="Ne nécessite pas de réponse","Ne nécessite pas de réponse",IF(T35="","",IF(V35<=0,"Dans les délais","Hors délais"))) -> Hors délais
A36: 20 | B36: 46034 | C36: N°0032911 du 12-01-2026 | D36: Structure fictive 18 | F36: REF-B N°003416 du 12-01-2026 | G36: Ordinaire | H36: =IFERROR(VLOOKUP(G36,Paramètres!$B$6:$F$8,2,FALSE()),"") -> 5 | I36: Transmission d'un rapport annuel fictif | J36: DSSE | K36: 46034 | L36: 46034 | N36: Agent DSSE n°2 | O36: 46045 | P36: =IF(G36="Ne nécessite pas de réponse","-",IF(AND(ISNUMBER(B36),ISNUMBER(O36)),O36-B36,"")) -> 11 | Q36: =IF(G36="Ne nécessite pas de réponse","-",IF(O36<>"","-",IF(OR(B36="",H36="",NOT(ISNUMBER(H36)),H36=0),"",IF((TODAY()-B36)/H36<=0.5,"VERT",IF((TODAY()-B36)/H36<=0.8,"JAUNE","ROUGE"))))) -> - | R36: =IFERROR(VLOOKUP(G36,Paramètres!$B$6:$F$8,3,FALSE()),"") -> 2 | S36: =IF(G36="Ne nécessite pas de réponse","-",IF(O36="","",IF(T36<>"","-",IF(OR(R36="",NOT(ISNUMBER(R36)),R36=0),"",IF((TODAY()-O36)/R36<=0.5,"VERT",IF((TODAY()-O36)/R36<=0.8,"JAUNE","ROUGE")))))) -> - | T36: 46049 | U36: =IF(G36="Ne nécessite pas de réponse","-",IF(AND(ISNUMBER(O36),ISNUMBER(T36)),T36-O36,"")) -> 4 | V36: =IF(G36="Ne nécessite pas de réponse","-",IF(AND(ISNUMBER(T36),ISNUMBER(B36),ISNUMBER(H36),ISNUMBER(R36)),T36-(B36+H36+R36),"")) -> 8 | W36: =IF(G36="Ne nécessite pas de réponse","Ne nécessite pas de réponse",IF(T36="","",IF(V36<=0,"Dans les délais","Hors délais"))) -> Hors délais
A37: 21 | B37: 46035 | C37: N°0005878 du 13-01-2026 | D37: Structure fictive 18 | E37: REF-A N°012059 du 13-01-2026 | F37: REF-B N°008402 du 13-01-2026 | G37: Ordinaire | H37: =IFERROR(VLOOKUP(G37,Paramètres!$B$6:$F$8,2,FALSE()),"") -> 5 | I37: Transmission de pièces justificatives fictives | J37: DSSE | K37: 46036 | L37: 46037 | M37: Analyse et proposition de réponse | N37: Agent DSSE n°1 | O37: 46041 | P37: =IF(G37="Ne nécessite pas de réponse","-",IF(AND(ISNUMBER(B37),ISNUMBER(O37)),O37-B37,"")) -> 6 | Q37: =IF(G37="Ne nécessite pas de réponse","-",IF(O37<>"","-",IF(OR(B37="",H37="",NOT(ISNUMBER(H37)),H37=0),"",IF((TODAY()-B37)/H37<=0.5,"VERT",IF((TODAY()-B37)/H37<=0.8,"JAUNE","ROUGE"))))) -> - | R37: =IFERROR(VLOOKUP(G37,Paramètres!$B$6:$F$8,3,FALSE()),"") -> 2 | S37: =IF(G37="Ne nécessite pas de réponse","-",IF(O37="","",IF(T37<>"","-",IF(OR(R37="",NOT(ISNUMBER(R37)),R37=0),"",IF((TODAY()-O37)/R37<=0.5,"VERT",IF((TODAY()-O37)/R37<=0.8,"JAUNE","ROUGE")))))) -> - | T37: 46044 | U37: =IF(G37="Ne nécessite pas de réponse","-",IF(AND(ISNUMBER(O37),ISNUMBER(T37)),T37-O37,"")) -> 3 | V37: =IF(G37="Ne nécessite pas de réponse","-",IF(AND(ISNUMBER(T37),ISNUMBER(B37),ISNUMBER(H37),ISNUMBER(R37)),T37-(B37+H37+R37),"")) -> 2 | W37: =IF(G37="Ne nécessite pas de réponse","Ne nécessite pas de réponse",IF(T37="","",IF(V37<=0,"Dans les délais","Hors délais"))) -> Hors délais
A38: 22 | B38: 46036 | C38: N°0026801 du 14-01-2026 | D38: Structure fictive 11 | F38: REF-B N°002375 du 14-01-2026 | G38: Ordinaire | H38: =IFERROR(VLOOKUP(G38,Paramètres!$B$6:$F$8,2,FALSE()),"") -> 5 | I38: Note de présentation d'un projet fictif | J38: DP | K38: 46036 | L38: 46036 | N38: Agent DP n°1 | O38: 46042 | P38: =IF(G38="Ne nécessite pas de réponse","-",IF(AND(ISNUMBER(B38),ISNUMBER(O38)),O38-B38,"")) -> 6 | Q38: =IF(G38="Ne nécessite pas de réponse","-",IF(O38<>"","-",IF(OR(B38="",H38="",NOT(ISNUMBER(H38)),H38=0),"",IF((TODAY()-B38)/H38<=0.5,"VERT",IF((TODAY()-B38)/H38<=0.8,"JAUNE","ROUGE"))))) -> - | R38: =IFERROR(VLOOKUP(G38,Paramètres!$B$6:$F$8,3,FALSE()),"") -> 2 | S38: =IF(G38="Ne nécessite pas de réponse","-",IF(O38="","",IF(T38<>"","-",IF(OR(R38="",NOT(ISNUMBER(R38)),R38=0),"",IF((TODAY()-O38)/R38<=0.5,"VERT",IF((TODAY()-O38)/R38<=0.8,"JAUNE","ROUGE")))))) -> - | T38: 46045 | U38: =IF(G38="Ne nécessite pas de réponse","-",IF(AND(ISNUMBER(O38),ISNUMBER(T38)),T38-O38,"")) -> 3 | V38: =IF(G38="Ne nécessite pas de réponse","-",IF(AND(ISNUMBER(T38),ISNUMBER(B38),ISNUMBER(H38),ISNUMBER(R38)),T38-(B38+H38+R38),"")) -> 2 | W38: =IF(G38="Ne nécessite pas de réponse","Ne nécessite pas de réponse",IF(T38="","",IF(V38<=0,"Dans les délais","Hors délais"))) -> Hors délais
A39: 23 | B39: 46036 | C39: N°0037355 du 14-01-2026 | D39: Structure fictive 04 | E39: REF-A N°005010 du 14-01-2026 | F39: REF-B N°004652 du 14-01-2026 | G39: Ordinaire | H39: =IFERROR(VLOOKUP(G39,Paramètres!$B$6:$F$8,2,FALSE()),"") -> 5 | I39: Demande de précisions sur un tableau de bord fictif | J39: DSSE | K39: 46036 | L39: 46036 | M39: Analyse et proposition de réponse | N39: Agent DSSE n°3 | O39: 46043 | P39: =IF(G39="Ne nécessite pas de réponse","-",IF(AND(ISNUMBER(B39),ISNUMBER(O39)),O39-B39,"")) -> 7 | Q39: =IF(G39="Ne nécessite pas de réponse","-",IF(O39<>"","-",IF(OR(B39="",H39="",NOT(ISNUMBER(H39)),H39=0),"",IF((TODAY()-B39)/H39<=0.5,"VERT",IF((TODAY()-B39)/H39<=0.8,"JAUNE","ROUGE"))))) -> - | R39: =IFERROR(VLOOKUP(G39,Paramètres!$B$6:$F$8,3,FALSE()),"") -> 2 | S39: =IF(G39="Ne nécessite pas de réponse","-",IF(O39="","",IF(T39<>"","-",IF(OR(R39="",NOT(ISNUMBER(R39)),R39=0),"",IF((TODAY()-O39)/R39<=0.5,"VERT",IF((TODAY()-O39)/R39<=0.8,"JAUNE","ROUGE")))))) -> - | T39: 46044 | U39: =IF(G39="Ne nécessite pas de réponse","-",IF(AND(ISNUMBER(O39),ISNUMBER(T39)),T39-O39,"")) -> 1 | V39: =IF(G39="Ne nécessite pas de réponse","-",IF(AND(ISNUMBER(T39),ISNUMBER(B39),ISNUMBER(H39),ISNUMBER(R39)),T39-(B39+H39+R39),"")) -> 1 | W39: =IF(G39="Ne nécessite pas de réponse","Ne nécessite pas de réponse",IF(T39="","",IF(V39<=0,"Dans les délais","Hors délais"))) -> Hors délais
A40: 24 | B40: 46036 | C40: N°0072110 du 14-01-2026 | D40: Structure fictive 11 | F40: REF-B N°004094 du 14-01-2026 | G40: Ordinaire | H40: =IFERROR(VLOOKUP(G40,Paramètres!$B$6:$F$8,2,FALSE()),"") -> 5 | I40: Transmission d'un rapport annuel fictif | J40: DSSE | K40: 46036 | L40: 46037 | M40: Vérifier la conformité avant signature | N40: Agent DSSE n°3 | O40: 46042 | P40: =IF(G40="Ne nécessite pas de réponse","-",IF(AND(ISNUMBER(B40),ISNUMBER(O40)),O40-B40,"")) -> 6 | Q40: =IF(G40="Ne nécessite pas de réponse","-",IF(O40<>"","-",IF(OR(B40="",H40="",NOT(ISNUMBER(H40)),H40=0),"",IF((TODAY()-B40)/H40<=0.5,"VERT",IF((TODAY()-B40)/H40<=0.8,"JAUNE","ROUGE"))))) -> - | R40: =IFERROR(VLOOKUP(G40,Paramètres!$B$6:$F$8,3,FALSE()),"") -> 2 | S40: =IF(G40="Ne nécessite pas de réponse","-",IF(O40="","",IF(T40<>"","-",IF(OR(R40="",NOT(ISNUMBER(R40)),R40=0),"",IF((TODAY()-O40)/R40<=0.5,"VERT",IF((TODAY()-O40)/R40<=0.8,"JAUNE","ROUGE")))))) -> - | T40: 46049 | U40: =IF(G40="Ne nécessite pas de réponse","-",IF(AND(ISNUMBER(O40),ISNUMBER(T40)),T40-O40,"")) -> 7 | V40: =IF(G40="Ne nécessite pas de réponse","-",IF(AND(ISNUMBER(T40),ISNUMBER(B40),ISNUMBER(H40),ISNUMBER(R40)),T40-(B40+H40+R40),"")) -> 6 | W40: =IF(G40="Ne nécessite pas de réponse","Ne nécessite pas de réponse",IF(T40="","",IF(V40<=0,"Dans les délais","Hors délais"))) -> Hors délais
A41: 25 | B41: 46036 | C41: N°0080245 du 14-01-2026 | D41: Structure fictive 02 | F41: REF-B N°005412 du 14-01-2026 | G41: Confidentiel | H41: =IFERROR(VLOOKUP(G41,Paramètres!$B$6:$F$8,2,FALSE()),"") -> 5 | I41: Demande de précisions sur un tableau de bord fictif | J41: DSSE | K41: 46037 | L41: 46038 | M41: À traiter en priorité | N41: Agent DSSE n°3 | O41: 46043 | P41: =IF(G41="Ne nécessite pas de réponse","-",IF(AND(ISNUMBER(B41),ISNUMBER(O41)),O41-B41,"")) -> 7 | Q41: =IF(G41="Ne nécessite pas de réponse","-",IF(O41<>"","-",IF(OR(B41="",H41="",NOT(ISNUMBER(H41)),H41=0),"",IF((TODAY()-B41)/H41<=0.5,"VERT",IF((TODAY()-B41)/H41<=0.8,"JAUNE","ROUGE"))))) -> - | R41: =IFERROR(VLOOKUP(G41,Paramètres!$B$6:$F$8,3,FALSE()),"") -> 2 | S41: =IF(G41="Ne nécessite pas de réponse","-",IF(O41="","",IF(T41<>"","-",IF(OR(R41="",NOT(ISNUMBER(R41)),R41=0),"",IF((TODAY()-O41)/R41<=0.5,"VERT",IF((TODAY()-O41)/R41<=0.8,"JAUNE","ROUGE")))))) -> - | T41: 46044 | U41: =IF(G41="Ne nécessite pas de réponse","-",IF(AND(ISNUMBER(O41),ISNUMBER(T41)),T41-O41,"")) -> 1 | V41: =IF(G41="Ne nécessite pas de réponse","-",IF(AND(ISNUMBER(T41),ISNUMBER(B41),ISNUMBER(H41),ISNUMBER(R41)),T41-(B41+H41+R41),"")) -> 1 | W41: =IF(G41="Ne nécessite pas de réponse","Ne nécessite pas de réponse",IF(T41="","",IF(V41<=0,"Dans les délais","Hors délais"))) -> Hors délais
A42: 26 | B42: 46036 | C42: N°0066911 du 14-01-2026 | D42: Structure fictive 11 | E42: REF-A N°005589 du 14-01-2026 | F42: REF-B N°009138 du 14-01-2026 | G42: Ordinaire | H42: =IFERROR(VLOOKUP(G42,Paramètres!$B$6:$F$8,2,FALSE()),"") -> 5 | I42: Transmission d'un rapport annuel fictif | J42: DSSE | K42: 46036 | L42: 46037 | M42: Suivi | N42: Agent DSSE n°2 | O42: 46041 | P42: =IF(G42="Ne nécessite pas de réponse","-",IF(AND(ISNUMBER(B42),ISNUMBER(O42)),O42-B42,"")) -> 5 | Q42: =IF(G42="Ne nécessite pas de réponse","-",IF(O42<>"","-",IF(OR(B42="",H42="",NOT(ISNUMBER(H42)),H42=0),"",IF((TODAY()-B42)/H42<=0.5,"VERT",IF((TODAY()-B42)/H42<=0.8,"JAUNE","ROUGE"))))) -> - | R42: =IFERROR(VLOOKUP(G42,Paramètres!$B$6:$F$8,3,FALSE()),"") -> 2 | S42: =IF(G42="Ne nécessite pas de réponse","-",IF(O42="","",IF(T42<>"","-",IF(OR(R42="",NOT(ISNUMBER(R42)),R42=0),"",IF((TODAY()-O42)/R42<=0.5,"VERT",IF((TODAY()-O42)/R42<=0.8,"JAUNE","ROUGE")))))) -> - | T42: 46042 | U42: =IF(G42="Ne nécessite pas de réponse","-",IF(AND(ISNUMBER(O42),ISNUMBER(T42)),T42-O42,"")) -> 1 | V42: =IF(G42="Ne nécessite pas de réponse","-",IF(AND(ISNUMBER(T42),ISNUMBER(B42),ISNUMBER(H42),ISNUMBER(R42)),T42-(B42+H42+R42),"")) -> -1 | W42: =IF(G42="Ne nécessite pas de réponse","Ne nécessite pas de réponse",IF(T42="","",IF(V42<=0,"Dans les délais","Hors délais"))) -> Dans les délais
...

Sheet Paramètres
B2: PARAMÈTRES DU DISPOSITIF DE SUIVI DU COURRIER - DSP
B4: DÉLAIS RÉGLEMENTAIRES (en jours)
B5: Type de courrier | C5: Délai agent (jours) | D5: Délai Directeur (jours) | E5: Délai total (jours) | F5: Description
B6: Ordinaire | C6: 5 | D6: 2 | E6: =C6+D6 -> 7 | F6: Courrier ordinaire - traitement par l'agent sous 5 jours, puis signature du Directeur sous 2 jours
B7: Confidentiel | C7: 5 | D7: 2 | E7: =C7+D7 -> 7 | F7: Courrier confidentiel - même délai que l'ordinaire
B8: Ne nécessite pas de réponse | C8: N/A | D8: N/A | E8: N/A | F8: Courrier sans objet - aucune réponse attendue
B10: DIVISIONS CONCERNÉES
B11: Code | C11: Libellé
B12: DRI | C12: Division des Relations Institutionnelles
B13: DP | C13: Division Portefeuille
B14: DSSE | C14: Division Suivi, Synthèse et des Études
B16: RÈGLES D'ALERTE SUR DÉLAI DE TRAITEMENT
B17: Code couleur | C17: Seuil de consommation | D17: Signification
B18: VERT | C18: ≤ 50% du délai consommé | D18: Traitement dans les temps - aucune action
B19: JAUNE | C19: > 50% et ≤ 80% du délai consommé | D19: Vigilance - relancer l'agent ou le Directeur
B20: ROUGE | C20: > 80% du délai ou délai dépassé | D20: Critique - intervention immédiate requise
B22: SYSTÈME D'ALERTE DIRECTEUR
B23: Le décompte du délai de signature du Directeur (2 jours) démarre automatiquement dès que l'agent soumet le dossier (date renseignée en colonne "Date de soumission du dossier par l'agent" de la feuille Suivi Courrier).
B24: La colonne "Alerte délai Directeur" applique les mêmes seuils que ci-dessus (VERT/JAUNE/ROUGE) sur ces 2 jours, et reste vide tant que le dossier n'a pas été soumis par l'agent.
